Workbook

Sheet Calendrier
A1: Projet 4 : Analyse des données de vente et retours
A2: Calendrier des sprints aligné sur les dates de remise communiquées par le professeur
A4: Sprint | B4: Début | C4: Fin | D4: Semaines | E4: Objectif du sprint | F4: Livrable remis | G4: Date de remise | H4: Poids dans la note | I4: Nb de tâches | J4: Charge estimée (h)
A5: Sprint 0 | B5: 21 sept. 2026 | C5: 4 oct. 2026 | D5: 2 | E5: Cadrage, collecte et recherche des données (dont tables de dimension), planification Scrum | F5: Livrables 1 et 2 : phases du projet et tâches granulaires + présentation PowerPoint UA1 | G5: 5 oct. 2026 | H5: 0.2 | I5: =COUNTIF(Tâches!$D$2:$D$212,A5) | J5: =SUMIF(Tâches!$D$2:$D$212,A5,Tâches!$G$2:$G$212)
A6: Sprint 1 | B6: 5 oct. 2026 | C6: 18 oct. 2026 | D6: 2 | E6: ETL sur trois exercices (2019 à 2021) : consolidation des ventes, modèle en flocon, charges, stock et ventes en ligne détaillées, pipeline reproductible | I6: =COUNTIF(Tâches!$D$2:$D$212,A6) | J6: =SUMIF(Tâches!$D$2:$D$212,A6,Tâches!$G$2:$G$212)
A7: Sprint 2 | B7: 19 oct. 2026 | C7: 1 nov. 2026 | D7: 2 | E7: Diagnostic de qualité, nettoyage et variables dérivées ; analyse Q1 (06b_q1_chute_des_ventes, 06_q1_facteurs_rentabilite) | I7: =COUNTIF(Tâches!$D$2:$D$212,A7) | J7: =SUMIF(Tâches!$D$2:$D$212,A7,Tâches!$G$2:$G$212)
A8: Sprint 3 | B8: 2 nov. 2026 | C8: 8 nov. 2026 | D8: 1 | E8: Analyse Q2 à Q5 (07, 08, 09), rapport L3 + L4 et présentation UA2 | F8: Livrable 3 : diagnostic, nettoyage et transformation, avec l'analyse exploratoire de Q1 à Q5 faite en avance (présentation UA2) | G8: 9 nov. 2026 | H8: 0.25 | I8: =COUNTIF(Tâches!$D$2:$D$212,A8) | J8: =SUMIF(Tâches!$D$2:$D$212,A8,Tâches!$G$2:$G$212)
A9: Sprint 4 | B9: 9 nov. 2026 | C9: 22 nov. 2026 | D9: 2 | E9: Prédictif et exploratoire : 10_prevision_ventes (régression), 11_grands_comptes (classification), 12_typologie_magasins (clustering) | I9: =COUNTIF(Tâches!$D$2:$D$212,A9) | J9: =SUMIF(Tâches!$D$2:$D$212,A9,Tâches!$G$2:$G$212)
A10: Sprint 5 | B10: 23 nov. 2026 | C10: 6 déc. 2026 | D10: 2 | E10: Prescriptif : 13_priorites_renouvellement (optimisation sous budget d'achat), 14_simulateur (recherche aléatoire et Monte-Carlo) ; application Streamlit (tableau de bord et simulateur), Power BI en option (Could) ; rapport et présentation UA3 | F10: Livrable 4 : modèles prédictifs et prescriptifs, application Streamlit, rapport et présentation (l'analyse exploratoire est remise avec le livrable 3) | G10: 7 déc. 2026 | H10: 0.35 | I10: =COUNTIF(Tâches!$D$2:$D$212,A10) | J10: =SUMIF(Tâches!$D$2:$D$212,A10,Tâches!$G$2:$G$212)
A11: Sprint 6 | B11: 7 déc. 2026 | C11: 13 déc. 2026 | D11: 1 | E11: Recommandations opérationnelles, plan d'essais des leviers incertains (section du rapport), rapport final | F11: Livrable 5 : rapport final avec recommandations opérationnelles | G11: 14 déc. 2026 | H11: 0.2 | I11: =COUNTIF(Tâches!$D$2:$D$212,A11) | J11: =SUMIF(Tâches!$D$2:$D$212,A11,Tâches!$G$2:$G$212)
A12: Total | D12: =SUM(D5:D11) | H12: =SUM(H5:H11) | I12: =SUM(I5:I11) | J12: =SUM(J5:J11)
A14: Hypothèses :
A15: 1. La présentation PowerPoint UA1 correspond au premier jalon (phases et tâches granulaires, remise du 5 octobre). À ajuster si l'UA1 a une autre date.
A16: 2. Source vérifiée : les données fournies correspondent à FactSales de Contoso Retail DW (2008-2009, dates décalées de 12 ans). Utilisation des tables de dimension sous réserve de validation par le professeur. Les fichiers fournis couvrent 5 catégories de produits sur 8 et les trimestres 1 à 3. Depuis le 6 octobre, avec l'accord du professeur, le projet travaille sur les ventes complètes des 56 boutiques (8 catégories, 8 trimestres), extraites de Contoso.
A17: 3. Les remises tombent un lundi : chaque sprint se termine le dimanche précédent.
A18: 4. Outils : Python et ses bibliothèques pour l'ETL, l'analyse, la modélisation et l'optimisation ; Streamlit pour le tableau de bord et le simulateur ; Power BI en option ; PowerPoint pour les présentations.
A19: Colonnes à remplir dans l'onglet Tâches (fond jaune) : Responsable et Statut.
A20: Mise à jour du 7 oct. 2026 : les analyses Q1 à Q5 (notebooks 06 à 09) sont terminées en avance. Les sprints et les dates de remise ne changent pas. Le contenu des sprints 5 et 6 est réorienté (onglet Changements).
A21: Mise à jour du 8 oct. 2026 : planning revu. L'ETL et l'analyse (Q1 à Q5) restent planifiés jusqu'au 8 novembre, alignés sur la remise du livrable 3 (présentation UA2), même si l'équipe a de l'avance. Les sprints 4 à 6 portent sur les notebooks 10 à 14 et l'application Streamlit. Les dates de remise ne changent pas. Les user stories et les tâches seront mises à jour au fil de l'avancement.

Sheet Gantt
A1: Diagramme de Gantt du projet
A2: Une colonne par semaine (du lundi au dimanche). Barres vertes : sprints. Barres claires : épopées actives pendant le sprint. Losange orange : remise d'un livrable.
A4: Élément | B4: Début | C4: Fin | D4: Durée (sem.) | E4: Sem. 1 21 sept. | F4: Sem. 2 28 sept. | G4: Sem. 3 5 oct. | H4: Sem. 4 12 oct. | I4: Sem. 5 19 oct. | J4: Sem. 6 26 oct. | K4: Sem. 7 2 nov. | L4: Sem. 8 9 nov. | M4: Sem. 9 16 nov. | N4: Sem. 10 23 nov. | O4: Sem. 11 30 nov. | P4: Sem. 12 7 déc. | Q4: Sem. 13 14 déc.
A5: SPRINTS
A6: Sprint 0 · Cadrage, collecte et recherche de données | B6: 21 sept. 2026 | C6: 4 oct. 2026 | D6: 2 | E6: Sprint 0
A7: Sprint 1 · ETL sur trois exercices et modèle de données | B7: 5 oct. 2026 | C7: 18 oct. 2026 | D7: 2 | G7: Sprint 1
A8: Sprint 2 · Diagnostic, nettoyage, variables et analyse Q1 | B8: 19 oct. 2026 | C8: 1 nov. 2026 | D8: 2 | I8: Sprint 2
A9: Sprint 3 · Analyse Q2 à Q5, rapport et présentation UA2 | B9: 2 nov. 2026 | C9: 8 nov. 2026 | D9: 1 | K9: Sprint 3
A10: Sprint 4 · Prévision, grands comptes, typologie (10, 11, 12) | B10: 9 nov. 2026 | C10: 22 nov. 2026 | D10: 2 | L10: Sprint 4
A11: Sprint 5 · Renouvellement, simulateur, Streamlit (13, 14), rapport UA3 | B11: 23 nov. 2026 | C11: 6 déc. 2026 | D11: 2 | N11: Sprint 5
A12: Sprint 6 · Recommandations, plan d'essais et rapport final | B12: 7 déc. 2026 | C12: 13 déc. 2026 | D12: 1 | P12: Sprint 6
A13: ÉPOPÉES (sprints où l'épopée a des tâches)
A14: E0 Gestion de projet Scrum | B14: 21 sept. 2026 | C14: 13 déc. 2026 | D14: 12
A15: E1 Collecte et recherche de données | B15: 21 sept. 2026 | C15: 4 oct. 2026 | D15: 2
A16: E2 Intégration et modélisation (ETL) | B16: 21 sept. 2026 | C16: 18 oct. 2026 | D16: 4
A17: E3 Qualité et nettoyage | B17: 19 oct. 2026 | C17: 1 nov. 2026 | D17: 2
A18: E4 Transformation et variables dérivées | B18: 2 nov. 2026 | C18: 8 nov. 2026 | D18: 1
A19: E5 Analyse exploratoire (Q1 à Q5) | B19: 9 nov. 2026 | C19: 6 déc. 2026 | D19: 4
A20: E6 Modélisation prédictive | B20: 9 nov. 2026 | C20: 6 déc. 2026 | D20: 4
A21: E7 Tableaux de bord | B21: 9 nov. 2026 | C21: 6 déc. 2026 | D21: 4
A22: E8 Documentation et livrables | B22: 21 sept. 2026 | C22: 13 déc. 2026 | D22: 6
A23: E9 Analyse prescriptive | B23: 23 nov. 2026 | C23: 13 déc. 2026 | D23: 3
A24: LIVRABLES (remise le lundi)
A25: L1 et L2 + présentation UA1 (20 %) | B25: 5 oct. 2026 | C25: 5 oct. 2026 | G25: ◆
A26: L3 · Diagnostic, nettoyage, transformation et analyse exploratoire, présentation UA2 (25 %) | B26: 9 nov. 2026 | C26: 9 nov. 2026 | L26: ◆
A27: L4 · Prédictif, prescriptif, Streamlit, rapport et présentation UA3 (35 %) | B27: 7 déc. 2026 | C27: 7 déc. 2026 | P27: ◆
A28: L5 · Rapport final (20 %) | B28: 14 déc. 2026 | C28: 14 déc. 2026 | Q28: ◆
A29: Action de grâce (férié) | B29: 12 oct. 2026 | C29: 12 oct. 2026 | H29: férié

Sheet Épopées
A1: ID | B1: Épopée | C1: Objectif | D1: Nb de user stories | E1: Charge estimée (h)
A2: E0 | B2: Gestion de projet Scrum | C2: Organiser l'équipe, planifier et suivre les sprints | D2: =COUNTIF(Backlog!$C$2:$C$43,A2) | E2: =SUMIF(Tâches!$C$2:$C$212,A2&" "&B2,Tâches!$G$2:$G$212)
A3: E1 | B3: Collecte et recherche de données | C3: Inventorier les données fournies, identifier les manques, collecter les tables de dimension et les données de contexte | D3: =COUNTIF(Backlog!$C$2:$C$43,A3) | E3: =SUMIF(Tâches!$C$2:$C$212,A3&" "&B3,Tâches!$G$2:$G$212)
A4: E2 | B4: Intégration et modélisation (ETL) | C4: Consolider les trimestres et construire un modèle en flocon exploitable par Python, Excel et Power BI | D4: =COUNTIF(Backlog!$C$2:$C$43,A4) | E4: =SUMIF(Tâches!$C$2:$C$212,A4&" "&B4,Tâches!$G$2:$G$212)
A5: E3 | B5: Qualité et nettoyage | C5: Diagnostiquer et corriger les anomalies | D5: =COUNTIF(Backlog!$C$2:$C$43,A5) | E5: =SUMIF(Tâches!$C$2:$C$212,A5&" "&B5,Tâches!$G$2:$G$212)
A6: E4 | B6: Transformation et variables dérivées | C6: Créer les indicateurs de marge, de retour et de remise | D6: =COUNTIF(Backlog!$C$2:$C$43,A6) | E6: =SUMIF(Tâches!$C$2:$C$212,A6&" "&B6,Tâches!$G$2:$G$212)
A7: E5 | B7: Analyse exploratoire (Q1 à Q5) | C7: Répondre aux questions de recherche en Python | D7: =COUNTIF(Backlog!$C$2:$C$43,A7) | E7: =SUMIF(Tâches!$C$2:$C$212,A7&" "&B7,Tâches!$G$2:$G$212)
A8: E6 | B8: Modélisation prédictive | C8: Prévoir les ventes par l'âge du catalogue, modéliser les charges selon les ventes, établir une typologie des magasins | D8: =COUNTIF(Backlog!$C$2:$C$43,A8) | E8: =SUMIF(Tâches!$C$2:$C$212,A8&" "&B8,Tâches!$G$2:$G$212)
A9: E7 | B9: Tableaux de bord | C9: Explorer d'autres modes de visualisation avec Excel, Power BI et une application Streamlit | D9: =COUNTIF(Backlog!$C$2:$C$43,A9) | E9: =SUMIF(Tâches!$C$2:$C$212,A9&" "&B9,Tâches!$G$2:$G$212)
A10: E8 | B10: Documentation et livrables | C10: Rapports, présentations PowerPoint et remises | D10: =COUNTIF(Backlog!$C$2:$C$43,A10) | E10: =SUMIF(Tâches!$C$2:$C$212,A10&" "&B10,Tâches!$G$2:$G$212)
A11: E9 | B11: Analyse prescriptive | C11: Simuler des scénarios de rentabilité, prioriser le renouvellement du catalogue et planifier les essais des leviers incertains | D11: =COUNTIF(Backlog!$C$2:$C$43,A11) | E11: =SUMIF(Tâches!$C$2:$C$212,A11&" "&B11,Tâches!$G$2:$G$212)
A12: Total | D12: =SUM(D2:D11) | E12: =SUM(E2:E11)

Sheet Backlog
A1: ID US | B1: User story | C1: Épopée | D1: Sprint | E1: Critère d'acceptation | F1: Priorité (MoSCoW) | G1: Points | H1: Nb de tâches | I1: Charge estimée (h) | J1: Tâches terminées | K1: État au 7 oct. 2026
A2: US01 | B2: En tant qu'équipe, je veux un cadre Scrum et un espace de travail commun afin de coordonner le projet. | C2: E0 | D2: Sprint 0 | E2: Rôles attribués, projet Jira ou GitHub Projects créé, dépôt GitHub structuré, Definition of Done rédigée | F2: Must | G2: 3 | H2: =COUNTIF(Tâches!$B$2:$B$212,A2) | I2: =SUMIF(Tâches!$B$2:$B$212,A2,Tâches!$G$2:$G$212) | J2: =COUNTIFS(Tâches!$B$2:$B$212,A2,Tâches!$I$2:$I$212,"Terminé") | K2: =IF(F2="Won't","Abandonnée",IF(J2+COUNTIFS(Tâches!$B$2:$B$212,A2,Tâches!$I$2:$I$212,"En cours")=0,"À faire",IF(J2+COUNTIFS(Tâches!$B$2:$B$212,A2,Tâches!$I$2:$I$212,"Écartée")>=H2,"Terminée","En cours")))
A3: US02 | B3: En tant qu'analyste, je veux inventorier les données fournies afin de connaître leur périmètre réel. | C3: E1 | D3: Sprint 0 | E3: Les 6 trimestres fournis sont chargés, décrits et un dictionnaire de données initial existe | F3: Must | G3: 3 | H3: =COUNTIF(Tâches!$B$2:$B$212,A3) | I3: =SUMIF(Tâches!$B$2:$B$212,A3,Tâches!$G$2:$G$212) | J3: =COUNTIFS(Tâches!$B$2:$B$212,A3,Tâches!$I$2:$I$212,"Terminé") | K3: =IF(F3="Won't","Abandonnée",IF(J3+COUNTIFS(Tâches!$B$2:$B$212,A3,Tâches!$I$2:$I$212,"En cours")=0,"À faire",IF(J3+COUNTIFS(Tâches!$B$2:$B$212,A3,Tâches!$I$2:$I$212,"Écartée")>=H3,"Terminée","En cours")))
A4: US03 | B4: En tant qu'analyste, je veux identifier les données manquantes afin de mesurer leur impact sur les questions de recherche. | C4: E1 | D4: Sprint 0 | E4: Tableau des manques et de leur impact validé par l'équipe, demande envoyée au professeur | F4: Must | G4: 2 | H4: =COUNTIF(Tâches!$B$2:$B$212,A4) | I4: =SUMIF(Tâches!$B$2:$B$212,A4,Tâches!$G$2:$G$212) | J4: =COUNTIFS(Tâches!$B$2:$B$212,A4,Tâches!$I$2:$I$212,"Terminé") | K4: =IF(F4="Won't","Abandonnée",IF(J4+COUNTIFS(Tâches!$B$2:$B$212,A4,Tâches!$I$2:$I$212,"En cours")=0,"À faire",IF(J4+COUNTIFS(Tâches!$B$2:$B$212,A4,Tâches!$I$2:$I$212,"Écartée")>=H4,"Terminée","En cours")))
A5: US04 | B5: En tant qu'analyste, je veux collecter les tables de dimension et le jeu de données complet afin d'enrichir l'analyse. | C5: E1 | D5: Sprint 0 | E5: Source vérifiée (FactSales de Contoso, décalage de 12 ans), arborescence des clés établie, 8 tables retenues et justifiées, correspondance des clés mesurée | F5: Must | G5: 8 | H5: =COUNTIF(Tâches!$B$2:$B$212,A5) | I5: =SUMIF(Tâches!$B$2:$B$212,A5,Tâches!$G$2:$G$212) | J5: =COUNTIFS(Tâches!$B$2:$B$212,A5,Tâches!$I$2:$I$212,"Terminé") | K5: =IF(F5="Won't","Abandonnée",IF(J5+COUNTIFS(Tâches!$B$2:$B$212,A5,Tâches!$I$2:$I$212,"En cours")=0,"À faire",IF(J5+COUNTIFS(Tâches!$B$2:$B$212,A5,Tâches!$I$2:$I$212,"Écartée")>=H5,"Terminée","En cours")))
A6: US05 | B6: En tant qu'analyste, je veux collecter des données de contexte afin d'interpréter les tendances 2020 et 2021. | C6: E1 | D6: Sprint 0 | E6: Calendrier des jours fériés et périodes COVID-19 par pays disponibles et documentés | F6: Should | G6: 3 | H6: =COUNTIF(Tâches!$B$2:$B$212,A6) | I6: =SUMIF(Tâches!$B$2:$B$212,A6,Tâches!$G$2:$G$212) | J6: =COUNTIFS(Tâches!$B$2:$B$212,A6,Tâches!$I$2:$I$212,"Terminé") | K6: =IF(F6="Won't","Abandonnée",IF(J6+COUNTIFS(Tâches!$B$2:$B$212,A6,Tâches!$I$2:$I$212,"En cours")=0,"À faire",IF(J6+COUNTIFS(Tâches!$B$2:$B$212,A6,Tâches!$I$2:$I$212,"Écartée")>=H6,"Terminée","En cours")))
A7: US06 | B7: En tant que Product Owner, je veux découper le projet en phases et jalons afin de respecter le calendrier du cours (Livrable 1). | C7: E0 | D7: Sprint 0 | E7: Phases, jalons et diagramme de Gantt alignés sur les dates de remise | F7: Must | G7: 2 | H7: =COUNTIF(Tâches!$B$2:$B$212,A7) | I7: =SUMIF(Tâches!$B$2:$B$212,A7,Tâches!$G$2:$G$212) | J7: =COUNTIFS(Tâches!$B$2:$B$212,A7,Tâches!$I$2:$I$212,"Terminé") | K7: =IF(F7="Won't","Abandonnée",IF(J7+COUNTIFS(Tâches!$B$2:$B$212,A7,Tâches!$I$2:$I$212,"En cours")=0,"À faire",IF(J7+COUNTIFS(Tâches!$B$2:$B$212,A7,Tâches!$I$2:$I$212,"Écartée")>=H7,"Terminée","En cours")))
A8: US07 | B8: En tant que Product Owner, je veux un backlog de tâches granulaires, estimées et priorisées (Livrable 2). | C8: E0 | D8: Sprint 0 | E8: Toutes les tâches ont une estimation, une priorité, un sprint et un responsable, saisies dans l'outil | F8: Must | G8: 5 | H8: =COUNTIF(Tâches!$B$2:$B$212,A8) | I8: =SUMIF(Tâches!$B$2:$B$212,A8,Tâches!$G$2:$G$212) | J8: =COUNTIFS(Tâches!$B$2:$B$212,A8,Tâches!$I$2:$I$212,"Terminé") | K8: =IF(F8="Won't","Abandonnée",IF(J8+COUNTIFS(Tâches!$B$2:$B$212,A8,Tâches!$I$2:$I$212,"En cours")=0,"À faire",IF(J8+COUNTIFS(Tâches!$B$2:$B$212,A8,Tâches!$I$2:$I$212,"Écartée")>=H8,"Terminée","En cours")))
A9: US08 | B9: En tant qu'équipe, je veux présenter le cadrage du projet (présentation UA1). | C9: E8 | D9: Sprint 0 | E9: Présentation PowerPoint remise et répétée, chaque membre a une partie | F9: Must | G9: 3 | H9: =COUNTIF(Tâches!$B$2:$B$212,A9) | I9: =SUMIF(Tâches!$B$2:$B$212,A9,Tâches!$G$2:$G$212) | J9: =COUNTIFS(Tâches!$B$2:$B$212,A9,Tâches!$I$2:$I$212,"Terminé") | K9: =IF(F9="Won't","Abandonnée",IF(J9+COUNTIFS(Tâches!$B$2:$B$212,A9,Tâches!$I$2:$I$212,"En cours")=0,"À faire",IF(J9+COUNTIFS(Tâches!$B$2:$B$212,A9,Tâches!$I$2:$I$212,"Écartée")>=H9,"Terminée","En cours")))
A10: US09 | B10: En tant qu'analyste, je veux une table de faits unique consolidant tous les trimestres de ventes (6 fournis, puis 8 avec les ventes complètes). | C10: E2 | D10: Sprint 1 | E10: Nombre de lignes et totaux réconciliés avec les fichiers sources, aucun doublon non expliqué | F10: Must | G10: 5 | H10: =COUNTIF(Tâches!$B$2:$B$212,A10) | I10: =SUMIF(Tâches!$B$2:$B$212,A10,Tâches!$G$2:$G$212) | J10: =COUNTIFS(Tâches!$B$2:$B$212,A10,Tâches!$I$2:$I$212,"Terminé") | K10: =IF(F10="Won't","Abandonnée",IF(J10+COUNTIFS(Tâches!$B$2:$B$212,A10,Tâches!$I$2:$I$212,"En cours")=0,"À faire",IF(J10+COUNTIFS(Tâches!$B$2:$B$212,A10,Tâches!$I$2:$I$212,"Écartée")>=H10,"Terminée","En cours")))
A11: US10 | B11: En tant qu'analyste, je veux un modèle en flocon afin d'analyser les ventes par boutique, produit, promotion et date. | C11: E2 | D11: Sprint 1 | E11: Schéma documenté, dimensions jointes, taux de correspondance des clés supérieur ou égal au seuil fixé | F11: Must | G11: 8 | H11: =COUNTIF(Tâches!$B$2:$B$212,A11) | I11: =SUMIF(Tâches!$B$2:$B$212,A11,Tâches!$G$2:$G$212) | J11: =COUNTIFS(Tâches!$B$2:$B$212,A11,Tâches!$I$2:$I$212,"Terminé") | K11: =IF(F11="Won't","Abandonnée",IF(J11+COUNTIFS(Tâches!$B$2:$B$212,A11,Tâches!$I$2:$I$212,"En cours")=0,"À faire",IF(J11+COUNTIFS(Tâches!$B$2:$B$212,A11,Tâches!$I$2:$I$212,"Écartée")>=H11,"Terminée","En cours")))
A12: US11 | B12: En tant que membre de l'équipe, je veux un pipeline reproductible exécutable en une seule commande afin que chacun obtienne les mêmes résultats. | C12: E2 | D12: Sprint 1 | E12: run_pipeline.py exécute tous les notebooks dans l'ordre des dépendances (en parallèle quand ils sont indépendants), testé sur un poste vierge, README à jour | F12: Must | G12: 5 | H12: =COUNTIF(Tâches!$B$2:$B$212,A12) | I12: =SUMIF(Tâches!$B$2:$B$212,A12,Tâches!$G$2:$G$212) | J12: =COUNTIFS(Tâches!$B$2:$B$212,A12,Tâches!$I$2:$I$212,"Terminé") | K12: =IF(F12="Won't","Abandonnée",IF(J12+COUNTIFS(Tâches!$B$2:$B$212,A12,Tâches!$I$2:$I$212,"En cours")=0,"À faire",IF(J12+COUNTIFS(Tâches!$B$2:$B$212,A12,Tâches!$I$2:$I$212,"Écartée")>=H12,"Terminée","En cours")))
A13: US12 | B13: En tant qu'analyste, je veux un diagnostic complet de la qualité des données. | C13: E3 | D13: Sprint 2 | E13: Rapport d'anomalies chiffré (manquants, incohérences, valeurs aberrantes) | F13: Must | G13: 8 | H13: =COUNTIF(Tâches!$B$2:$B$212,A13) | I13: =SUMIF(Tâches!$B$2:$B$212,A13,Tâches!$G$2:$G$212) | J13: =COUNTIFS(Tâches!$B$2:$B$212,A13,Tâches!$I$2:$I$212,"Terminé") | K13: =IF(F13="Won't","Abandonnée",IF(J13+COUNTIFS(Tâches!$B$2:$B$212,A13,Tâches!$I$2:$I$212,"En cours")=0,"À faire",IF(J13+COUNTIFS(Tâches!$B$2:$B$212,A13,Tâches!$I$2:$I$212,"Écartée")>=H13,"Terminée","En cours")))
... A43: US42 | B43: En tant qu'utilisateur métier, je veux une application Streamlit reprenant les quatre pages du tableau de bord afin de les consulter sans Power BI. | C43: E7 | D43: Sprint 5 | E43: Application lancée en une commande, 4 pages (vue d'ensemble, catalogue, magasins et charges, simulateur), chiffres identiques à ceux des notebooks | F43: Should | G43: 8 | H43: =COUNTIF(Tâches!$B$2:$B$212,A43) | I43: =SUMIF(Tâches!$B$2:$B$212,A43,Tâches!$G$2:$G$212) | J43: =COUNTIFS(Tâches!$B$2:$B$212,A43,Tâches!$I$2:$I$212,"Terminé") | K43: =IF(F43="Won't","Abandonnée",IF(J43+COUNTIFS(Tâches!$B$2:$B$212,A43,Tâches!$I$2:$I$212,"En cours")=0,"À faire",IF(J43+COUNTIFS(Tâches!$B$2:$B$212,A43,Tâches!$I$2:$I$212,"Écartée")>=H43,"Terminée","En cours")))
A44: Total | G44: =SUM(G2:G43) | H44: =SUM(H2:H43) | I44: =SUM(I2:I43) | J44: =SUM(J2:J43)
A46: Points : suite de Fibonacci (1, 2, 3, 5, 8). MoSCoW : Must = indispensable, Should = important, Could = souhaitable. Won't = écarté (voir l'onglet Changements).
A47: Colonnes J et K : calculées à partir de l'onglet Tâches. Terminée = toutes les tâches non écartées sont terminées. Abandonnée = priorité Won't.

Sheet Tâches
A1: ID tâche | B1: ID US | C1: Épopée | D1: Sprint | E1: Tâche | F1: Outil | G1: Estimation (h) | H1: Responsable | I1: Statut | J1: Date de fin prévue | K1: Date de fin réelle | L1: Commentaire (mise à jour du 7 oct. 2026)
A2: T001 | B2: US01 | C2: E0 Gestion de projet Scrum | D2: Sprint 0 | E2: Définir les rôles : Product Owner, Scrum Master, développeurs | F2: Réunion | G2: 1 | H2: Toute l'équipe | I2: Terminé | J2: 4 oct. 2026
A3: T002 | B3: US01 | C3: E0 Gestion de projet Scrum | D3: Sprint 0 | E3: Créer le projet dans Jira ou GitHub Projects et inviter l'équipe | F3: Jira / GitHub Projects | G3: 1 | H3: Achraf | I3: Terminé | J3: 4 oct. 2026
A4: T003 | B4: US01 | C4: E0 Gestion de projet Scrum | D4: Sprint 0 | E4: Rédiger la Definition of Done et les conventions (nommage, branches, notebooks) | F4: Word / GitHub | G4: 1.5 | H4: Achraf | I4: Terminé | J4: 4 oct. 2026
A5: T004 | B5: US33 | C5: E2 Intégration et modélisation (ETL) | D5: Sprint 0 | E5: Définir l'arborescence du dépôt (data : raw, interim, clean, outputs ; notebooks par phase ; src ; tests ; dashboards ; reports) | F5: GitHub | G5: 1 | H5: Yacine | I5: Terminé | J5: 4 oct. 2026
A6: T005 | B6: US33 | C6: E2 Intégration et modélisation (ETL) | D6: Sprint 0 | E6: Créer les squelettes des 16 notebooks numérotés (00 à 15) avec leurs sections et un responsable par notebook | F6: Jupyter | G6: 1.5 | H6: Yacine | I6: Terminé | J6: 4 oct. 2026
A7: T006 | B7: US33 | C7: E2 Intégration et modélisation (ETL) | D7: Sprint 0 | E7: Configurer l'environnement (.venv, requirements.txt, config.py, .gitignore, README) | F7: Python / Git | G7: 1 | H7: Yacine | I7: Terminé | J7: 4 oct. 2026
A8: T007 | B8: US33 | C8: E2 Intégration et modélisation (ETL) | D8: Sprint 0 | E8: Créer la charte graphique commune (src/viz.py : couleurs, police, format des montants, enregistrement des figures) | F8: Python (matplotlib) | G8: 1 | H8: Yacine | I8: Terminé | J8: 4 oct. 2026
A9: T008 | B9: US02 | C9: E1 Collecte et recherche de données | D9: Sprint 0 | E9: Charger chaque fichier trimestriel et relever lignes, colonnes, types et période couverte (00_inventaire) | F9: Python (pandas) | G9: 2 | H9: Yacine | I9: Terminé | J9: 4 oct. 2026
A10: T009 | B10: US02 | C10: E1 Collecte et recherche de données | D10: Sprint 0 | E10: Vérifier la présence des 8 trimestres 2020 et 2021 et la continuité des dates (6 présents : T4 2020 et 2021 absents) | F10: Python (pandas) | G10: 1 | H10: Yacine | I10: Terminé | J10: 4 oct. 2026
A11: T010 | B11: US02 | C11: E1 Collecte et recherche de données | D11: Sprint 0 | E11: Rédiger le dictionnaire de données initial des 14 variables (dictionnaire_donnees.xlsx) | F11: Excel | G11: 2 | H11: Barnabé | I11: Terminé | J11: 4 oct. 2026
A12: T011 | B12: US03 | C12: E1 Collecte et recherche de données | D12: Sprint 0 | E12: Lister les dimensions et informations manquantes (boutique, produit, promotion, client, retours, stocks, charges) | F12: Excel | G12: 1.5 | H12: Barnabé | I12: Terminé | J12: 4 oct. 2026
A13: T012 | B13: US03 | C13: E1 Collecte et recherche de données | D13: Sprint 0 | E13: Évaluer l'impact de chaque manque sur les questions Q1 à Q5 | F13: Excel | G13: 1.5 | H13: Barnabé | I13: Terminé | J13: 4 oct. 2026
... A38: T037 | B38: US27 | C38: E0 Gestion de projet Scrum | D38: Sprint 0 | E38: Sprint 0 : planification, revue et rétrospective | F38: Réunion | G38: 2 | H38: Achraf | I38: Terminé | J38: 4 oct. 2026
A39: T038 | B39: US09 | C39: E2 Intégration et modélisation (ETL) | D39: Sprint 1 | E39: Écrire le script de chargement des fichiers de ventes (data/raw/contoso/Sales) | F39: Python (pandas) | G39: 2 | H39: Yacine | I39: Terminé | J39: 18 oct. 2026 | K39: 6 oct. 2026 | L39: Notebook 01_etl, exécuté sur les ventes complètes
A40: T039 | B40: US09 | C40: E2 Intégration et modélisation (ETL) | D40: Sprint 1 | E40: Harmoniser noms de colonnes, types et dates, convertir les montants texte (« $1,062.60 ») en nombres | F40: Python (pandas) | G40: 2 | H40: Yacine | I40: Terminé | J40: 18 oct. 2026 | K40: 6 oct. 2026 | L40: Notebook 01_etl, exécuté sur les ventes complètes
A41: T040 | B41: US09 | C41: E2 Intégration et modélisation (ETL) | D41: Sprint 1 | E41: Concaténer les trimestres avec une colonne source (année, trimestre) | F41: Python (pandas) | G41: 1 | H41: Yacine | I41: Terminé | J41: 18 oct. 2026 | K41: 6 oct. 2026 | L41: Notebook 01_etl, exécuté sur les ventes complètes
A42: T041 | B42: US09 | C42: E2 Intégration et modélisation (ETL) | D42: Sprint 1 | E42: Contrôler les doublons d'IdVente entre trimestres | F42: Python (pandas) | G42: 1.5 | H42: Barnabé | I42: Terminé | J42: 18 oct. 2026 | K42: 6 oct. 2026 | L42: Notebook 01_etl, exécuté sur les ventes complètes
A43: T042 | B43: US09 | C43: E2 Intégration et modélisation (ETL) | D43: Sprint 1 | E43: Réconcilier lignes et totaux (ventes, coûts, retours) avant et après consolidation | F43: Python (pandas) | G43: 2 | H43: Barnabé | I43: Terminé | J43: 18 oct. 2026 | K43: 6 oct. 2026 | L43: Notebook 01_etl, exécuté sur les ventes complètes
A44: T043 | B44: US10 | C44: E2 Intégration et modélisation (ETL) | D44: Sprint 1 | E44: Concevoir le schéma en flocon (faits ventes, boutique → géographie, produit → sous-catégorie → catégorie, promotion, date, canal, devise) | F44: draw.io / Power BI | G44: 2 | H44: Mouncif | I44: Terminé | J44: 18 oct. 2026 | K44: 6 oct. 2026 | L44: Notebook 02_flocon, exécuté sur les ventes complètes
A45: T044 | B45: US10 | C45: E2 Intégration et modélisation (ETL) | D45: Sprint 1 | E45: Réaligner les dates des dimensions sur nos données (+12 ans : promotions, ouverture et fermeture des boutiques, produits) | F45: Python (pandas) | G45: 1 | H45: Mouncif | I45: Terminé | J45: 18 oct. 2026 | K45: 6 oct. 2026 | L45: Notebook 02_flocon, exécuté sur les ventes complètes
A46: T045 | B46: US10 | C46: E2 Intégration et modélisation (ETL) | D46: Sprint 1 | E46: Joindre le canal et la devise récupérés depuis FactSales | F46: Python (pandas) | G46: 1 | H46: Mouncif | I46: Terminé | J46: 18 oct. 2026 | K46: 6 oct. 2026 | L46: Notebook 02_flocon, exécuté sur les ventes complètes
A47: T046 | B47: US10 | C47: E2 Intégration et modélisation (ETL) | D47: Sprint 1 | E47: Construire la dimension date (jour, semaine, mois, trimestre, jour férié, période COVID) | F47: Python (pandas) | G47: 2 | H47: Yacine | I47: Terminé | J47: 18 oct. 2026 | K47: 6 oct. 2026 | L47: Notebook 02_flocon, exécuté sur les ventes complètes
A48: T047 | B48: US10 | C48: E2 Intégration et modélisation (ETL) | D48: Sprint 1 | E48: Aplatir la hiérarchie produit (produit, sous-catégorie, catégorie) et géographie (ville, région, pays) | F48: Python (pandas) | G48: 2 | H48: Yacine | I48: Terminé | J48: 18 oct. 2026 | K48: 6 oct. 2026 | L48: Notebook 02_flocon, exécuté sur les ventes complètes
A49: T048 | B49: US10 | C49: E2 Intégration et modélisation (ETL) | D49: Sprint 1 | E49: Joindre les dimensions à la table de faits et mesurer le taux de correspondance | F49: Python (pandas) | G49: 2 | H49: Mouncif | I49: Terminé | J49: 18 oct. 2026 | K49: 6 oct. 2026 | L49: Notebook 02_flocon, exécuté sur les ventes complètes
A50: T049 | B50: US10 | C50: E2 Intégration et modélisation (ETL) | D50: Sprint 1 | E50: Traiter les clés sans correspondance (membre « Inconnu ») et documenter | F50: Python (pandas) | G50: 1.5 | H50: Mouncif | I50: Terminé | J50: 18 oct. 2026 | K50: 6 oct. 2026 | L50: Notebook 02_flocon, exécuté sur les ventes complètes
A51: T050 | B51: US10 | C51: E2 Intégration et modélisation (ETL) | D51: Sprint 1 | E51: Exporter les tables consolidées et jointes dans data/interim (Parquet et CSV) | F51: Python (pandas) | G51: 1 | H51: Mouncif | I51: Terminé | J51: 18 oct. 2026 | K51: 6 oct. 2026 | L51: Notebook 02_flocon, exécuté sur les ventes complètes
A52: T051 | B52: US11 | C52: E2 Intégration et modélisation (ETL) | D52: Sprint 1 | E52: Factoriser le code partagé dans src/ (config, etl, qualite, features, modeles, viz) | F52: Python | G52: 3 | H52: À répartir | I52: En cours | J52: 18 oct. 2026 | L52: config, etl, viz et analyse existent ; les autres modules restent à créer (à confirmer)
A53: T052 | B53: US11 | C53: E2 Intégration et modélisation (ETL) | D53: Sprint 1 | E53: Écrire run_pipeline.py (papermill : ordre des dépendances, exécution parallèle des notebooks indépendants, copies exécutées) | F53: Python (papermill) | G53: 3 | H53: À répartir | I53: À faire | J53: 18 oct. 2026
A54: T053 | B54: US11 | C54: E2 Intégration et modélisation (ETL) | D54: Sprint 1 | E54: Tester l'exécution complète sur un poste vierge | F54: Python | G54: 1 | H54: À répartir | I54: À faire | J54: 18 oct. 2026
A55: T054 | B55: US11 | C55: E2 Intégration et modélisation (ETL) | D55: Sprint 1 | E55: Rédiger le README d'exécution du pipeline | F55: GitHub | G55: 1 | H55: À répartir | I55: À faire | J55: 18 oct. 2026
A56: T055 | B56: US11 | C56: E2 Intégration et modélisation (ETL) | D56: Sprint 1 | E56: Revue de code croisée du pipeline | F56: GitHub | G56: 1.5 | H56: Barnabé | I56: À faire | J56: 18 oct. 2026
A57: T056 | B57: US27 | C57: E0 Gestion de projet Scrum | D57: Sprint 1 | E57: Sprint 1 : planification, revue et rétrospective | F57: Réunion | G57: 2 | H57: Achraf | I57: À faire | J57: 18 oct. 2026
A58: T057 | B58: US12 | C58: E3 Qualité et nettoyage | D58: Sprint 2 | E58: Mesurer le taux de valeurs manquantes par variable | F58: Python (pandas) | G58: 1 | H58: Yacine | I58: Terminé | J58: 1 nov. 2026 | K58: 6 oct. 2026 | L58: Notebook 03_diagnostic, exécuté sur les ventes complètes
A59: T058 | B59: US12 | C59: E3 Qualité et nettoyage | D59: Sprint 2 | E59: Détecter les valeurs nulles ou négatives (quantités, prix, coûts, montants) | F59: Python (pandas) | G59: 1.5 | H59: Yacine | I59: Terminé | J59: 1 nov. 2026 | K59: 6 oct. 2026 | L59: Notebook 03_diagnostic, exécuté sur les ventes complètes
A60: T059 | B60: US12 | C60: E3 Qualité et nettoyage | D60: Sprint 2 | E60: Contrôler : Montant des ventes = Prix unitaire × Quantité − Remise | F60: Python (pandas) | G60: 1.5 | H60: Barnabé | I60: Terminé | J60: 1 nov. 2026 | K60: 6 oct. 2026 | L60: Notebook 03_diagnostic, exécuté sur les ventes complètes
A61: T060 | B61: US12 | C61: E3 Qualité et nettoyage | D61: Sprint 2 | E61: Contrôler : Coût total = Coût unitaire × Quantité | F61: Python (pandas) | G61: 1 | H61: Barnabé | I61: Terminé | J61: 1 nov. 2026 | K61: 6 oct. 2026 | L61: Notebook 03_diagnostic, exécuté sur les ventes complètes
A62: T061 | B62: US12 | C62: E3 Qualité et nettoyage | D62: Sprint 2 | E62: Contrôler : quantités et montants de retour inférieurs ou égaux aux ventes | F62: Python (pandas) | G62: 1 | H62: Yacine | I62: Terminé | J62: 1 nov. 2026 | K62: 6 oct. 2026 | L62: Notebook 03_diagnostic, exécuté sur les ventes complètes
A63: T062 | B63: US12 | C63: E3 Qualité et nettoyage | D63: Sprint 2 | E63: Contrôler : Quantité de remise inférieure ou égale à la Quantité de vente | F63: Python (pandas) | G63: 1 | H63: Yacine | I63: Terminé | J63: 1 nov. 2026 | K63: 6 oct. 2026 | L63: Notebook 03_diagnostic, exécuté sur les ventes complètes
A64: T063 | B64: US12 | C64: E3 Qualité et nettoyage | D64: Sprint 2 | E64: Contrôler la cohérence promotion et remise (promo sans remise, remise sans promo) | F64: Python (pandas) | G64: 1.5 | H64: Yacine | I64: Terminé | J64: 1 nov. 2026 | K64: 6 oct. 2026 | L64: Notebook 03_diagnostic, exécuté sur les ventes complètes
...

Sheet Changements
A1: Date | B1: Élément | C1: Changement | D1: Raison | E1: Statut dans Jira
A2: 6 oct. 2026 | B2: Périmètre des données | C2: Passage des fichiers fournis (5 catégories, trimestres 1 à 3, 144 874 lignes) aux ventes complètes des 56 boutiques (8 catégories, 8 trimestres, 376 234 lignes) | D2: Seul périmètre comparable aux charges du plan stratégique ; les catégories absentes pèsent plus de la moitié du chiffre d'affaires ; fin d'année et promotion des Fêtes présentes | E2: Sans objet
A3: 6 oct. 2026 | B3: US34 (nouvelle, Must) | C3: Étendre les ventes au périmètre complet : 8 tâches T167 à T174, dont 7 déjà terminées | D3: Travail réalisé le 6 octobre, à tracer dans le backlog | E3: À créer
A4: 6 oct. 2026 | B4: US35 (nouvelle, Should) | C4: Rentabilité nette par boutique à partir des charges du plan stratégique : 5 tâches T175 à T179 | D4: Les charges par boutique existent dans Contoso et se rapprochent de nos ventes au cent près | E4: À créer
A5: 6 oct. 2026 | B5: US36 (nouvelle, Should) | C5: Dépenses de publicité face aux promotions : 3 tâches T180 à T182 | D5: Complète Q2 et Q5 | E5: À créer
A6: 6 oct. 2026 | B6: US37 (nouvelle, Could) | C6: Détail des ventes en ligne pour comprendre les remises : 3 tâches T183 à T185 | D6: Seule table transactionnelle de la base, limitée au canal en ligne | E6: À créer
A7: 6 oct. 2026 | B7: US28 | C7: Priorité Must -> Could (modèle prédictif du risque de retour) | D7: L'énoncé demande d'identifier les déterminants des retours (US19, US21) et des modèles prédictifs de ventes (US23), pas un modèle prédictif des retours | E7: À modifier
A8: 6 oct. 2026 | B8: US30 | C8: Priorité Must -> Could (simulation de scénarios what-if) | D8: La stratégie d'optimisation demandée est couverte par US31 | E8: À modifier
A9: 6 oct. 2026 | B9: US32 | C9: Priorité Must -> Could (analyse de sensibilité et calendrier promotionnel) | D9: Les recommandations opérationnelles demandées sont couvertes par US26 | E9: À modifier
A10: 6 oct. 2026 | B10: US09 | C10: Libellé : « tous les trimestres de ventes (6 fournis, puis 8) » | D10: Suite du changement de périmètre | E10: À modifier
A11: 6 oct. 2026 | B11: Nettoyage | C11: Nouvelle règle N6 : quantité remisée ramenée à la quantité vendue sur 386 lignes. Aucun montant modifié : le chiffre d'affaires reste égal à celui du plan stratégique | D11: Anomalie apparue avec la catégorie Home Appliances ; démarche détaillée dans 03_diagnostic et dans le L3 | E11: Sans objet
A12: 7 oct. 2026 | B12: Orientation du projet | C12: Les deux premiers leviers de rentabilité sont le renouvellement du catalogue et la maîtrise des charges, et non les promotions et les retours. Les sprints 5 et 6 sont réorientés en conséquence. | D12: Résultats des notebooks 06 à 09 : catalogue en place −152 M$ en 2021, charges en hausse pendant que les ventes baissent, promotions sans effet mesuré sur les ventes, retours uniformes et peu coûteux | E12: Sans objet
... A29: 7 oct. 2026 | B29: US16 (livrable 3) | C29: Première version du rapport rédigée : T067, T082, T083 et T084 passent à « En revue » | D29: Rédaction en avance sur le sprint 3. Reste la relecture par l'équipe (T086) | E29: À modifier
A31: Les documents remis le 5 octobre (L1, L2, présentation UA1) ne sont pas modifiés : cet onglet et le L3 expliquent les changements.
